2023-08-09 06:13:27,161 -  nornir.core -     INFO -        run() - Running task 'random_configs' with args {} on 2 hosts
2023-08-09 06:13:31,658 - nornir.core.task -    ERROR -      start() - Host 'EOS2': task 'send_configs_from_file' failed with traceback:
Traceback (most recent call last):
  File "/usr/local/lib/python3.7/dist-packages/nornir/core/task.py", line 99, in start
    r = self.task(self, **self.params)
  File "/usr/local/lib/python3.7/dist-packages/nornir_scrapli/tasks/core/send_configs_from_file.py", line 58, in send_configs_from_file
    scrapli_conn = task.host.get_connection("scrapli", task.nornir.config)
  File "/usr/local/lib/python3.7/dist-packages/nornir/core/inventory.py", line 502, in get_connection
    extras=conn.extras,
  File "/usr/local/lib/python3.7/dist-packages/nornir/core/inventory.py", line 553, in open_connection
    configuration=configuration,
  File "/usr/local/lib/python3.7/dist-packages/nornir_scrapli/connection.py", line 105, in open
    connection.open()
  File "/usr/local/lib/python3.7/dist-packages/scrapli/driver/base/sync_driver.py", line 95, in open
    auth_private_key_passphrase=self.auth_private_key_passphrase,
  File "/usr/local/lib/python3.7/dist-packages/scrapli/decorators.py", line 229, in decorate
    kwargs=kwargs,
  File "/usr/local/lib/python3.7/dist-packages/scrapli/decorators.py", line 114, in _multiprocessing_timeout
    return future.result()
  File "/usr/lib/python3.7/concurrent/futures/_base.py", line 425, in result
    return self.__get_result()
  File "/usr/lib/python3.7/concurrent/futures/_base.py", line 384, in __get_result
    raise self._exception
  File "/usr/lib/python3.7/concurrent/futures/thread.py", line 57, in run
    result = self.fn(*self.args, **self.kwargs)
  File "/usr/local/lib/python3.7/dist-packages/scrapli/channel/sync_channel.py", line 300, in channel_authenticate_ssh
    raise ScrapliAuthenticationFailed(msg)
scrapli.exceptions.ScrapliAuthenticationFailed: password prompt seen more than once, assuming auth failed

2023-08-09 06:13:31,659 - nornir.core.task -    ERROR -      start() - Host 'EOS2': task 'random_configs' failed with traceback:
Traceback (most recent call last):
  File "/usr/local/lib/python3.7/dist-packages/nornir/core/task.py", line 99, in start
    r = self.task(self, **self.params)
  File "2cicd.py", line 13, in random_configs
    task.run(task=send_configs_from_file, file="configtest.txt")
  File "/usr/local/lib/python3.7/dist-packages/nornir/core/task.py", line 174, in run
    raise NornirSubTaskError(task=run_task, result=r)
nornir.core.exceptions.NornirSubTaskError: Subtask: send_configs_from_file (failed)


2023-08-09 06:13:31,736 - nornir.core.task -    ERROR -      start() - Host 'EOS1': task 'send_configs_from_file' failed with traceback:
Traceback (most recent call last):
  File "/usr/local/lib/python3.7/dist-packages/nornir/core/task.py", line 99, in start
    r = self.task(self, **self.params)
  File "/usr/local/lib/python3.7/dist-packages/nornir_scrapli/tasks/core/send_configs_from_file.py", line 58, in send_configs_from_file
    scrapli_conn = task.host.get_connection("scrapli", task.nornir.config)
  File "/usr/local/lib/python3.7/dist-packages/nornir/core/inventory.py", line 502, in get_connection
    extras=conn.extras,
  File "/usr/local/lib/python3.7/dist-packages/nornir/core/inventory.py", line 553, in open_connection
    configuration=configuration,
  File "/usr/local/lib/python3.7/dist-packages/nornir_scrapli/connection.py", line 105, in open
    connection.open()
  File "/usr/local/lib/python3.7/dist-packages/scrapli/driver/base/sync_driver.py", line 95, in open
    auth_private_key_passphrase=self.auth_private_key_passphrase,
  File "/usr/local/lib/python3.7/dist-packages/scrapli/decorators.py", line 229, in decorate
    kwargs=kwargs,
  File "/usr/local/lib/python3.7/dist-packages/scrapli/decorators.py", line 114, in _multiprocessing_timeout
    return future.result()
  File "/usr/lib/python3.7/concurrent/futures/_base.py", line 425, in result
    return self.__get_result()
  File "/usr/lib/python3.7/concurrent/futures/_base.py", line 384, in __get_result
    raise self._exception
  File "/usr/lib/python3.7/concurrent/futures/thread.py", line 57, in run
    result = self.fn(*self.args, **self.kwargs)
  File "/usr/local/lib/python3.7/dist-packages/scrapli/channel/sync_channel.py", line 300, in channel_authenticate_ssh
    raise ScrapliAuthenticationFailed(msg)
scrapli.exceptions.ScrapliAuthenticationFailed: password prompt seen more than once, assuming auth failed

2023-08-09 06:13:31,736 - nornir.core.task -    ERROR -      start() - Host 'EOS1': task 'random_configs' failed with traceback:
Traceback (most recent call last):
  File "/usr/local/lib/python3.7/dist-packages/nornir/core/task.py", line 99, in start
    r = self.task(self, **self.params)
  File "2cicd.py", line 13, in random_configs
    task.run(task=send_configs_from_file, file="configtest.txt")
  File "/usr/local/lib/python3.7/dist-packages/nornir/core/task.py", line 174, in run
    raise NornirSubTaskError(task=run_task, result=r)
nornir.core.exceptions.NornirSubTaskError: Subtask: send_configs_from_file (failed)


2023-08-09 06:14:22,680 -  nornir.core -     INFO -        run() - Running task 'random_configs' with args {} on 2 hosts
2023-08-10 07:34:28,005 -  nornir.core -     INFO -        run() - Running task 'random_configs' with args {} on 2 hosts
2023-08-10 07:34:43,036 - nornir.core.task -    ERROR -      start() - Host 'EOS2': task 'send_configs_from_file' failed with traceback:
Traceback (most recent call last):
  File "/usr/local/lib/python3.7/dist-packages/nornir/core/task.py", line 99, in start
    r = self.task(self, **self.params)
  File "/usr/local/lib/python3.7/dist-packages/nornir_scrapli/tasks/core/send_configs_from_file.py", line 58, in send_configs_from_file
    scrapli_conn = task.host.get_connection("scrapli", task.nornir.config)
  File "/usr/local/lib/python3.7/dist-packages/nornir/core/inventory.py", line 502, in get_connection
    extras=conn.extras,
  File "/usr/local/lib/python3.7/dist-packages/nornir/core/inventory.py", line 553, in open_connection
    configuration=configuration,
  File "/usr/local/lib/python3.7/dist-packages/nornir_scrapli/connection.py", line 105, in open
    connection.open()
  File "/usr/local/lib/python3.7/dist-packages/scrapli/driver/base/sync_driver.py", line 95, in open
    auth_private_key_passphrase=self.auth_private_key_passphrase,
  File "/usr/local/lib/python3.7/dist-packages/scrapli/decorators.py", line 229, in decorate
    kwargs=kwargs,
  File "/usr/local/lib/python3.7/dist-packages/scrapli/decorators.py", line 114, in _multiprocessing_timeout
    return future.result()
  File "/usr/lib/python3.7/concurrent/futures/_base.py", line 425, in result
    return self.__get_result()
  File "/usr/lib/python3.7/concurrent/futures/_base.py", line 384, in __get_result
    raise self._exception
  File "/usr/lib/python3.7/concurrent/futures/thread.py", line 57, in run
    result = self.fn(*self.args, **self.kwargs)
  File "/usr/local/lib/python3.7/dist-packages/scrapli/channel/sync_channel.py", line 288, in channel_authenticate_ssh
    self._ssh_message_handler(output=authenticate_buf)
  File "/usr/local/lib/python3.7/dist-packages/scrapli/channel/base_channel.py", line 459, in _ssh_message_handler
    raise ScrapliAuthenticationFailed(msg)
scrapli.exceptions.ScrapliAuthenticationFailed: Timed out connecting to host

2023-08-10 07:34:43,036 - nornir.core.task -    ERROR -      start() - Host 'EOS2': task 'random_configs' failed with traceback:
Traceback (most recent call last):
  File "/usr/local/lib/python3.7/dist-packages/nornir/core/task.py", line 99, in start
    r = self.task(self, **self.params)
  File "2cicd.py", line 15, in random_configs
    task.run(task=send_configs_from_file, file="configtest.txt")
  File "/usr/local/lib/python3.7/dist-packages/nornir/core/task.py", line 174, in run
    raise NornirSubTaskError(task=run_task, result=r)
nornir.core.exceptions.NornirSubTaskError: Subtask: send_configs_from_file (failed)


2023-08-10 07:34:43,135 - nornir.core.task -    ERROR -      start() - Host 'EOS1': task 'send_configs_from_file' failed with traceback:
Traceback (most recent call last):
  File "/usr/local/lib/python3.7/dist-packages/nornir/core/task.py", line 99, in start
    r = self.task(self, **self.params)
  File "/usr/local/lib/python3.7/dist-packages/nornir_scrapli/tasks/core/send_configs_from_file.py", line 58, in send_configs_from_file
    scrapli_conn = task.host.get_connection("scrapli", task.nornir.config)
  File "/usr/local/lib/python3.7/dist-packages/nornir/core/inventory.py", line 502, in get_connection
    extras=conn.extras,
  File "/usr/local/lib/python3.7/dist-packages/nornir/core/inventory.py", line 553, in open_connection
    configuration=configuration,
  File "/usr/local/lib/python3.7/dist-packages/nornir_scrapli/connection.py", line 105, in open
    connection.open()
  File "/usr/local/lib/python3.7/dist-packages/scrapli/driver/base/sync_driver.py", line 95, in open
    auth_private_key_passphrase=self.auth_private_key_passphrase,
  File "/usr/local/lib/python3.7/dist-packages/scrapli/decorators.py", line 229, in decorate
    kwargs=kwargs,
  File "/usr/local/lib/python3.7/dist-packages/scrapli/decorators.py", line 114, in _multiprocessing_timeout
    return future.result()
  File "/usr/lib/python3.7/concurrent/futures/_base.py", line 425, in result
    return self.__get_result()
  File "/usr/lib/python3.7/concurrent/futures/_base.py", line 384, in __get_result
    raise self._exception
  File "/usr/lib/python3.7/concurrent/futures/thread.py", line 57, in run
    result = self.fn(*self.args, **self.kwargs)
  File "/usr/local/lib/python3.7/dist-packages/scrapli/channel/sync_channel.py", line 288, in channel_authenticate_ssh
    self._ssh_message_handler(output=authenticate_buf)
  File "/usr/local/lib/python3.7/dist-packages/scrapli/channel/base_channel.py", line 459, in _ssh_message_handler
    raise ScrapliAuthenticationFailed(msg)
scrapli.exceptions.ScrapliAuthenticationFailed: Timed out connecting to host

2023-08-10 07:34:43,135 - nornir.core.task -    ERROR -      start() - Host 'EOS1': task 'random_configs' failed with traceback:
Traceback (most recent call last):
  File "/usr/local/lib/python3.7/dist-packages/nornir/core/task.py", line 99, in start
    r = self.task(self, **self.params)
  File "2cicd.py", line 15, in random_configs
    task.run(task=send_configs_from_file, file="configtest.txt")
  File "/usr/local/lib/python3.7/dist-packages/nornir/core/task.py", line 174, in run
    raise NornirSubTaskError(task=run_task, result=r)
nornir.core.exceptions.NornirSubTaskError: Subtask: send_configs_from_file (failed)


2023-08-10 07:44:29,264 -  nornir.core -     INFO -        run() - Running task 'random_configs' with args {} on 2 hosts
2023-08-10 07:44:34,567 - nornir.core.task -    ERROR -      start() - Host 'EOS1': task 'send_configs_from_file' failed with traceback:
Traceback (most recent call last):
  File "/usr/local/lib/python3.7/dist-packages/nornir/core/task.py", line 99, in start
    r = self.task(self, **self.params)
  File "/usr/local/lib/python3.7/dist-packages/nornir_scrapli/tasks/core/send_configs_from_file.py", line 58, in send_configs_from_file
    scrapli_conn = task.host.get_connection("scrapli", task.nornir.config)
  File "/usr/local/lib/python3.7/dist-packages/nornir/core/inventory.py", line 502, in get_connection
    extras=conn.extras,
  File "/usr/local/lib/python3.7/dist-packages/nornir/core/inventory.py", line 553, in open_connection
    configuration=configuration,
  File "/usr/local/lib/python3.7/dist-packages/nornir_scrapli/connection.py", line 105, in open
    connection.open()
  File "/usr/local/lib/python3.7/dist-packages/scrapli/driver/base/sync_driver.py", line 95, in open
    auth_private_key_passphrase=self.auth_private_key_passphrase,
  File "/usr/local/lib/python3.7/dist-packages/scrapli/decorators.py", line 229, in decorate
    kwargs=kwargs,
  File "/usr/local/lib/python3.7/dist-packages/scrapli/decorators.py", line 114, in _multiprocessing_timeout
    return future.result()
  File "/usr/lib/python3.7/concurrent/futures/_base.py", line 425, in result
    return self.__get_result()
  File "/usr/lib/python3.7/concurrent/futures/_base.py", line 384, in __get_result
    raise self._exception
  File "/usr/lib/python3.7/concurrent/futures/thread.py", line 57, in run
    result = self.fn(*self.args, **self.kwargs)
  File "/usr/local/lib/python3.7/dist-packages/scrapli/channel/sync_channel.py", line 300, in channel_authenticate_ssh
    raise ScrapliAuthenticationFailed(msg)
scrapli.exceptions.ScrapliAuthenticationFailed: password prompt seen more than once, assuming auth failed

2023-08-10 07:44:34,567 - nornir.core.task -    ERROR -      start() - Host 'EOS1': task 'random_configs' failed with traceback:
Traceback (most recent call last):
  File "/usr/local/lib/python3.7/dist-packages/nornir/core/task.py", line 99, in start
    r = self.task(self, **self.params)
  File "2cicd.py", line 15, in random_configs
    task.run(task=send_configs_from_file, file="configtest.txt")
  File "/usr/local/lib/python3.7/dist-packages/nornir/core/task.py", line 174, in run
    raise NornirSubTaskError(task=run_task, result=r)
nornir.core.exceptions.NornirSubTaskError: Subtask: send_configs_from_file (failed)


2023-08-10 07:44:34,600 - nornir.core.task -    ERROR -      start() - Host 'EOS2': task 'send_configs_from_file' failed with traceback:
Traceback (most recent call last):
  File "/usr/local/lib/python3.7/dist-packages/nornir/core/task.py", line 99, in start
    r = self.task(self, **self.params)
  File "/usr/local/lib/python3.7/dist-packages/nornir_scrapli/tasks/core/send_configs_from_file.py", line 58, in send_configs_from_file
    scrapli_conn = task.host.get_connection("scrapli", task.nornir.config)
  File "/usr/local/lib/python3.7/dist-packages/nornir/core/inventory.py", line 502, in get_connection
    extras=conn.extras,
  File "/usr/local/lib/python3.7/dist-packages/nornir/core/inventory.py", line 553, in open_connection
    configuration=configuration,
  File "/usr/local/lib/python3.7/dist-packages/nornir_scrapli/connection.py", line 105, in open
    connection.open()
  File "/usr/local/lib/python3.7/dist-packages/scrapli/driver/base/sync_driver.py", line 95, in open
    auth_private_key_passphrase=self.auth_private_key_passphrase,
  File "/usr/local/lib/python3.7/dist-packages/scrapli/decorators.py", line 229, in decorate
    kwargs=kwargs,
  File "/usr/local/lib/python3.7/dist-packages/scrapli/decorators.py", line 114, in _multiprocessing_timeout
    return future.result()
  File "/usr/lib/python3.7/concurrent/futures/_base.py", line 425, in result
    return self.__get_result()
  File "/usr/lib/python3.7/concurrent/futures/_base.py", line 384, in __get_result
    raise self._exception
  File "/usr/lib/python3.7/concurrent/futures/thread.py", line 57, in run
    result = self.fn(*self.args, **self.kwargs)
  File "/usr/local/lib/python3.7/dist-packages/scrapli/channel/sync_channel.py", line 300, in channel_authenticate_ssh
    raise ScrapliAuthenticationFailed(msg)
scrapli.exceptions.ScrapliAuthenticationFailed: password prompt seen more than once, assuming auth failed

2023-08-10 07:44:34,600 - nornir.core.task -    ERROR -      start() - Host 'EOS2': task 'random_configs' failed with traceback:
Traceback (most recent call last):
  File "/usr/local/lib/python3.7/dist-packages/nornir/core/task.py", line 99, in start
    r = self.task(self, **self.params)
  File "2cicd.py", line 15, in random_configs
    task.run(task=send_configs_from_file, file="configtest.txt")
  File "/usr/local/lib/python3.7/dist-packages/nornir/core/task.py", line 174, in run
    raise NornirSubTaskError(task=run_task, result=r)
nornir.core.exceptions.NornirSubTaskError: Subtask: send_configs_from_file (failed)


2023-08-10 07:45:52,771 -  nornir.core -     INFO -        run() - Running task 'random_configs' with args {} on 2 hosts
2023-08-10 07:46:50,392 -  nornir.core -     INFO -        run() - Running task 'random_configs' with args {} on 2 hosts
2023-08-10 07:48:50,846 -  nornir.core -     INFO -        run() - Running task 'random_configs' with args {} on 1 hosts
2023-08-10 07:48:57,145 -  nornir.core -     INFO -        run() - Running task 'random_configs' with args {} on 1 hosts
